<mujoco model="arm_robot">
  <worldbody>
    <body name="base" pos="0 0 0.1">
      <geom type="box" size="0.1 0.1 0.05" rgba="0.3 0.3 0.3 1"/>
      <joint name="joint1" type="hinge" pos="0 0 0.1" axis="0 0 1"/>
      <body name="link1" pos="0 0 0.2">
        <geom type="capsule" size="0.05 0.2" rgba="0.5 0.5 0.8 1"/>
        <joint name="joint2" type="hinge" pos="0 0 0.4" axis="0 1 0"/>
        <body name="link2" pos="0 0 0.4">
          <geom type="capsule" size="0.05 0.2" rgba="0.8 0.5 0.5 1"/>
          <joint name="joint3" type="hinge" pos="0 0 0.6" axis="1 0 0"/>
          <body name="end_effector" pos="0 0 0.8">
            <geom type="sphere" size="0.05" rgba="1 0 0 1"/>
          </body>
        </body>
      </body>
    </body>
  </worldbody>
  <actuator>
    <motor joint="joint1" ctrlrange="-1 1" ctrllimited="true"/>
    <motor joint="joint2" ctrlrange="-1 1" ctrllimited="true"/>
    <motor joint="joint3" ctrlrange="-1 1" ctrllimited="true"/>
  </actuator>
</mujoco>